Workbook

Sheet Cover
D1: Vectorlab - OWASP ASVS Checklist | I1: DIG - MDPO25.A.1
I3: Rev. 0.0 | J3: 46136
B6: Cliente | E6: <Cliente>
B7: Progetto | E7: <Progetto>
B8: Livello di classificazione | E8: Interno
B10: Rev. | C10: Data | D10: Descrizione | H10: Redatto | I10: Approvato | J10: Classificazione
B11: 0.0 | C11: gg/mmm/aaa | D11: Prima emissione | H11: Area Digital | I11: CTO | J11: Interno

Sheet Results
A1: Results
A3: Current ASVS version | B3: 4.0.3
A4: Level want to obtain | B4: 1
A6: Category | B6: Valid | C6: Invalid | D6: Not Applicable | E6: Total criteria | F6: Validity Percentage | G6: ASVS Level Acquired
A7: V1 - Architecture, Design and Threat Modeling | B7: =COUNTIF('V1 - Architecture, Design and T'!$H$2:$H$43,"Valid") -> 0 | C7: =COUNTIF('V1 - Architecture, Design and T'!$H$2:$H$43,"Invalid") -> 0 | D7: =COUNTIF('V1 - Architecture, Design and T'!$H$2:$H$43,"Not applicable") -> 0 | E7: {=COUNTIF('V1 - Architecture, Design and T'!H2:H43,{"Valid";"Invalid"})} -> 0 | F7: =IF(E7=0,1,ROUND((B7/E7),1)) -> 1
A8: V2 - Authentication | B8: =COUNTIF('V2 - Authentication'!$H$2:$H$58,"Valid") -> 0 | C8: =COUNTIF('V2 - Authentication'!$H$2:$H$58,"Invalid") -> 0 | D8: =COUNTIF('V2 - Authentication'!$H$2:$H$58,"Not applicable") -> 0 | E8: {=COUNTIF('V2 - Authentication'!H2:H58,{"Valid";"Invalid"})} -> 0 | F8: =IF(E8=0,1,ROUND((B8/E8),1)) -> 1
A9: V3 - Session Management | B9: =COUNTIF('V3 - Session Management'!$H$2:$H$21,"Valid") -> 0 | C9: =COUNTIF('V3 - Session Management'!$H$2:$H$21,"Invalid") -> 0 | D9: =COUNTIF('V3 - Session Management'!$H$2:$H$21,"Not applicable") -> 0 | E9: {=COUNTIF('V3 - Session Management'!H2:H21,{"Valid";"Invalid"})} -> 0 | F9: =IF(E9=0,1,ROUND((B9/E9),1)) -> 1
A10: V4 - Access Control | B10: =COUNTIF('V4 - Access Control'!$H$2:$H$11,"Valid") -> 0 | C10: =COUNTIF('V4 - Access Control'!$H$2:$H$11,"Invalid") -> 0 | D10: =COUNTIF('V4 - Access Control'!$H$2:$H$11,"Not applicable") -> 0 | E10: {=COUNTIF('V4 - Access Control'!H2:H11,{"Valid";"Invalid"})} -> 0 | F10: =IF(E10=0,1,ROUND((B10/E10),1)) -> 1
A11: V5 - Validation, Sanitization and Encoding | B11: =COUNTIF('V5 - Validation, Sanitization a'!$H$2:$H$31,"Valid") -> 0 | C11: =COUNTIF('V5 - Validation, Sanitization a'!$H$2:$H$31,"Invalid") -> 0 | D11: =COUNTIF('V5 - Validation, Sanitization a'!$H$2:$H$31,"Not applicable") -> 0 | E11: {=COUNTIF('V5 - Validation, Sanitization a'!H2:H31,{"Valid";"Invalid"})} -> 0 | F11: =IF(E11=0,1,ROUND((B11/E11),1)) -> 1
A12: V6 - Stored Cryptography | B12: =COUNTIF('V6 - Stored Cryptography'!$H$2:$H$17,"Valid") -> 0 | C12: =COUNTIF('V6 - Stored Cryptography'!$H$2:$H$17,"Invalid") -> 0 | D12: =COUNTIF('V6 - Stored Cryptography'!$H$2:$H$17,"Not applicable") -> 0 | E12: {=COUNTIF('V6 - Stored Cryptography'!H2:H17,{"Valid";"Invalid"})} -> 0 | F12: =IF(E12=0,1,ROUND((B12/E12),1)) -> 1
A13: V7 - Error Handling and Logging | B13: =COUNTIF('V7 - Error Handling and Logging'!$H$2:$H$14,"Valid") -> 0 | C13: =COUNTIF('V7 - Error Handling and Logging'!$H$2:$H$14,"Invalid") -> 0 | D13: =COUNTIF('V7 - Error Handling and Logging'!$H$2:$H$14,"Not applicable") -> 0 | E13: {=COUNTIF('V7 - Error Handling and Logging'!H2:H14,{"Valid";"Invalid"})} -> 0 | F13: =IF(E13=0,1,ROUND((B13/E13),1)) -> 1
A14: V8 - Data Protection | B14: =COUNTIF('V8 - Data Protection'!$H$2:$H$18,"Valid") -> 0 | C14: =COUNTIF('V8 - Data Protection'!$H$2:$H$18,"Invalid") -> 0 | D14: =COUNTIF('V8 - Data Protection'!$H$2:$H$18,"Not applicable") -> 0 | E14: {=COUNTIF('V8 - Data Protection'!H2:H18,{"Valid";"Invalid"})} -> 0 | F14: =IF(E14=0,1,ROUND((B14/E14),1)) -> 1
A15: V9 - Communication | B15: =COUNTIF('V9 - Communication'!$H$2:$H$9,"Valid") -> 0 | C15: =COUNTIF('V9 - Communication'!$H$2:$H$9,"Invalid") -> 0 | D15: =COUNTIF('V9 - Communication'!$H$2:$H$9,"Not applicable") -> 0 | E15: {=COUNTIF('V9 - Communication'!H2:H9,{"Valid";"Invalid"})} -> 0 | F15: =IF(E15=0,1,ROUND((B15/E15),1)) -> 1
A16: V10 - Malicious Code | B16: =COUNTIF('V10 - Malicious Code'!$H$2:$H$11,"Valid") -> 0 | C16: =COUNTIF('V10 - Malicious Code'!$H$2:$H$11,"Invalid") -> 0 | D16: =COUNTIF('V10 - Malicious Code'!$H$2:$H$11,"Not applicable") -> 0 | E16: {=COUNTIF('V10 - Malicious Code'!H2:H11,{"Valid";"Invalid"})} -> 0 | F16: =IF(E16=0,1,ROUND((B16/E16),1)) -> 1
A17: V11 - Business Logic | B17: =COUNTIF('V11 - Business Logic'!$H$2:$H$9,"Valid") -> 0 | C17: =COUNTIF('V11 - Business Logic'!$H$2:$H$9,"Invalid") -> 0 | D17: =COUNTIF('V11 - Business Logic'!$H$2:$H$9,"Not applicable") -> 0 | E17: {=COUNTIF('V11 - Business Logic'!H2:H9,{"Valid";"Invalid"})} -> 0 | F17: =IF(E17=0,1,ROUND((B17/E17),1)) -> 1
A18: V12 - Files and Resources | B18: =COUNTIF('V12 - Files and Resources'!$H$2:$H$16,"Valid") -> 0 | C18: =COUNTIF('V12 - Files and Resources'!$H$2:$H$16,"Invalid") -> 0 | D18: =COUNTIF('V12 - Files and Resources'!$H$2:$H$16,"Not applicable") -> 0 | E18: {=COUNTIF('V12 - Files and Resources'!H2:H16,{"Valid";"Invalid"})} -> 0 | F18: =IF(E18=0,1,ROUND((B18/E18),1)) -> 1
A19: V13 - API and Web Service | B19: =COUNTIF('V13 - API and Web Service'!$H$2:$H$16,"Valid") -> 0 | C19: =COUNTIF('V13 - API and Web Service'!$H$2:$H$16,"Invalid") -> 0 | D19: =COUNTIF('V13 - API and Web Service'!$H$2:$H$16,"Not applicable") -> 0 | E19: {=COUNTIF('V13 - API and Web Service'!H2:H16,{"Valid";"Invalid"})} -> 0 | F19: =IF(E19=0,1,ROUND((B19/E19),1)) -> 1
A20: V14 - Configuration | B20: =COUNTIF('V14 - Configuration'!$H$2:$H$26,"Valid") -> 0 | C20: =COUNTIF('V14 - Configuration'!$H$2:$H$26,"Invalid") -> 0 | D20: =COUNTIF('V14 - Configuration'!$H$2:$H$26,"Not applicable") -> 0 | E20: {=COUNTIF('V14 - Configuration'!H2:H26,{"Valid";"Invalid"})} -> 0 | F20: =IF(E20=0,1,ROUND((B20/E20),1)) -> 1
A22: Total | B22: =SUM(B7:B20) -> 0 | C22: =SUM(C7:C20) -> 0 | D22: =SUM(D7:D20) -> 0 | E22: =SUM(E7:E20) -> 0 | F22: =ROUND(AVERAGE(F7:F20), 1) -> 1

Sheet Usage
A1: Using the ASVS ASVS has two main goals: to help organizations develop and maintain secure applications. to allow security service vendors, security tools vendors, and consumers to align their requirements and offerings.
A3: Application Security Verification Levels The Application Security Verification Standard defines three security verification levels, with each level increasing in depth. ASVS Level 1 is for low assurance levels, and is completely penetration testable ASVS Level 2 is for applications that contain sensitive data, which requires protection and is the recommended level for most apps ASVS Level 3 is for the most critical applications - applications that perform high value transactions, contain sensitive medical data, or any application that requires the highest level of trust. Each ASVS level contains a list of security requirements. Each of these requirements can also be mapped to security-specific features and capabilities that must be built into software by developers.
A5: How to use this standard One of the best ways to use the Application Security Verification Standard is to use it as a blueprint to create a Secure Coding Checklist specific to your application, platform or organization. Tailoring the ASVS to your use cases will increase the focus on the security requirements that are most important to your projects and environments.
A7: Level 1 - First steps, automated, or whole of portfolio view An application achieves ASVS Level 1 if it adequately defends against application security vulnerabilities that are easy to discover, and included in the OWASP Top 10 and other similar checklists. Level 1 is the bare minimum that all applications should strive for. It is also useful as a first step in a multi-phase effort or when applications do not store or handle sensitive data and therefore do not need the more rigorous controls of Level 2 or 3. Level 1 controls can be checked either automatically by tools or simply manually without access to source code. We consider Level 1 the minimum required for all applications. Threats to the application will most likely be from attackers who are using simple and low effort techniques to identify easy-to-find and easy-to-exploit vulnerabilities. This is in contrast to a determined attacker who will spend focused energy to specifically target the application. If data processed by your application has high value, you would rarely want to stop at a Level 1 review. | C7: Level 2 - Most applications An application achieves ASVS Level 2 (or Standard) if it adequately defends against most of the risks associated with software today. Level 2 ensures that security controls are in place, effective, and used within the application. Level 2 is typically appropriate for applications that handle significant business-to-business transactions, including those that process healthcare information, implement business-critical or sensitive functions, or process other sensitive assets, or industries where integrity is a critical facet to protect their business, such as the game industry to thwart cheaters and game hacks. Threats to Level 2 applications will typically be skilled and motivated attackers focusing on specific targets using tools and techniques that are highly practiced and effective at discovering and exploiting weaknesses within applications.
A9: Level 3 - High value, high assurance, or high safety ASVS Level 3 is the highest level of verification within the ASVS. This level is typically reserved for applications that require significant levels of security verification, such as those that may be found within areas of military, health and safety, critical infrastructure, etc. Organizations may require ASVS Level 3 for applications that perform critical functions, where failure could significantly impact the organization's operations, and even its survivability. Example guidance on the application of ASVS Level 3 is provided below. An application achieves ASVS Level 3 (or Advanced) if it adequately defends against advanced application security vulnerabilities and also demonstrates principles of good security design. An application at ASVS Level 3 requires more in depth analysis of architecture, coding, and testing than all the other levels. A secure application is modularized in a meaningful way (to facilitate resiliency, scalability, and most of all, layers of security), and each module (separated by network connection and/or physical instance) takes care of its own security responsibilities (defense in depth), that need to be properly documented. Responsibilities include controls for ensuring confidentiality (e.g. encryption), integrity (e.g. transactions, input validation), availability (e.g. handling load gracefully), authentication (including between systems), authorization, and auditing (logging).

Sheet V1 - Architecture, Design and T
A1: # | B1: Control Objective | C1: # | D1: ASVS Level | E1: CWE | F1: NIST | G1: Verification Requirement | H1: Valid | I1: Source Code Reference | J1: Comment | K1: Tool Used | L1: Scope
A2: V1.1 | B2: Secure Software Development Lifecycle | C2: 1.1.1 | D2: 2 | G2: Verify the use of a secure software development lifecycle that addresses security in all stages of development. ([C1](https://owasp.org/www-project-proactive-controls/#div-numbering))
C3: 1.1.2 | D3: 2 | E3: 1053 | G3: Verify the use of threat modeling for every design change or sprint planning to identify threats, plan for countermeasures, facilitate appropriate risk responses, and guide security testing.
C4: 1.1.3 | D4: 2 | E4: 1110 | G4: Verify that all user stories and features contain functional security constraints, such as "As a user, I should be able to view and edit my profile. I should not be able to view or edit anyone else's profile"
C5: 1.1.4 | D5: 2 | E5: 1059 | G5: Verify documentation and justification of all the application's trust boundaries, components, and significant data flows.
C6: 1.1.5 | D6: 2 | E6: 1059 | G6: Verify definition and security analysis of the application's high-level architecture and all connected remote services. ([C1](https://owasp.org/www-project-proactive-controls/#div-numbering))
C7: 1.1.6 | D7: 2 | E7: 637 | G7: Verify implementation of centralized, simple (economy of design), vetted, secure, and reusable security controls to avoid duplicate, missing, ineffective, or insecure controls. ([C10](https://owasp.org/www-project-proactive-controls/#div-numbering))
C8: 1.1.7 | D8: 2 | E8: 637 | G8: Verify availability of a secure coding checklist, security requirements, guideline, or policy to all developers and testers.
A9: V1.2 | B9: Authentication Architecture | C9: 1.2.1 | D9: 2 | E9: 250 | G9: Verify the use of unique or special low-privilege operating system accounts for all application components, services, and servers. ([C3](https://owasp.org/www-project-proactive-controls/#div-numbering))
C10: 1.2.2 | D10: 2 | E10: 306 | G10: Verify that communications between application components, including APIs, middleware and data layers, are authenticated. Components should have the least necessary privileges needed. ([C3](https://owasp.org/www-project-proactive-controls/#div-numbering))
C11: 1.2.3 | D11: 2 | E11: 306 | G11: Verify that the application uses a single vetted authentication mechanism that is known to be secure, can be extended to include strong authentication, and has sufficient logging and monitoring to detect account abuse or breaches.
C12: 1.2.4 | D12: 2 | E12: 306 | G12: Verify that all authentication pathways and identity management APIs implement consistent authentication security control strength, such that there are no weaker alternatives per the risk of the application.
A13: V1.4 | B13: Access Control Architecture | C13: 1.4.1 | D13: 2 | E13: 602 | G13: Verify that trusted enforcement points such as at access control gateways, servers, and serverless functions enforce access controls. Never enforce access controls on the client.
C14: 1.4.2 | G14: [DELETED, NOT ACTIONABLE]
C15: 1.4.3 | G15: [DELETED, DUPLICATE OF 4.1.3]
C16: 1.4.4 | D16: 2 | E16: 284 | G16: Verify the application uses a single and well-vetted access control mechanism for accessing protected data and resources. All requests must pass through this single mechanism to avoid copy and paste or insecure alternative paths. ([C7](https://owasp.org/www-project-proactive-controls/#div-numbering))
C17: 1.4.5 | D17: 2 | E17: 275 | G17: Verify that attribute or feature-based access control is used whereby the code checks the user's authorization for a feature/data item rather than just their role. Permissions should still be allocated using roles. ([C7](https://owasp.org/www-project-proactive-controls/#div-numbering))
A18: V1.5 | B18: Input and Output Architecture | C18: 1.5.1 | D18: 2 | E18: 1029 | G18: Verify that input and output requirements clearly define how to handle and process data based on type, content, and applicable laws, regulations, and other policy compliance.
C19: 1.5.2 | D19: 2 | E19: 502 | G19: Verify that serialization is not used when communicating with untrusted clients. If this is not possible, ensure that adequate integrity controls (and possibly encryption if sensitive data is sent) are enforced to prevent deserialization attacks including object injection.
C20: 1.5.3 | D20: 2 | E20: 602 | G20: Verify that input validation is enforced on a trusted service layer. ([C5](https://owasp.org/www-project-proactive-controls/#div-numbering))
C21: 1.5.4 | D21: 2 | E21: 116 | G21: Verify that output encoding occurs close to or by the interpreter for which it is intended. ([C4](https://www.owasp.org/index.php/OWASP_Proactive_Controls#tab=Formal_Numbering))
A22: V1.6 | B22: Cryptographic Architecture | C22: 1.6.1 | D22: 2 | E22: 320 | G22: Verify that there is an explicit policy for management of cryptographic keys and that a cryptographic key lifecycle follows a key management standard such as NIST SP 800-57.
C23: 1.6.2 | D23: 2 | E23: 320 | G23: Verify that consumers of cryptographic services protect key material and other secrets by using key vaults or API based alternatives.
C24: 1.6.3 | D24: 2 | E24: 320 | G24: Verify that all keys and passwords are replaceable and are part of a well-defined process to re-encrypt sensitive data.
C25: 1.6.4 | D25: 2 | E25: 320 | G25: Verify that the architecture treats client-side secrets--such as symmetric keys, passwords, or API tokens--as insecure and never uses them to protect or access sensitive data.
A26: V1.7 | B26: Errors, Logging and Auditing Architecture | C26: 1.7.1 | D26: 2 | E26: 1009 | G26: Verify that a common logging format and approach is used across the system. ([C9](https://owasp.org/www-project-proactive-controls/#div-numbering))
C27: 1.7.2 | D27: 2 | G27: Verify that logs are securely transmitted to a preferably remote system for analysis, detection, alerting, and escalation. ([C9](https://owasp.org/www-project-proactive-controls/#div-numbering))
A28: V1.8 | B28: Data Protection and Privacy Architecture | C28: 1.8.1 | D28: 2 | G28: Verify that all sensitive data is identified and classified into protection levels.
C29: 1.8.2 | D29: 2 | G29: Verify that all protection levels have an associated set of protection requirements, such as encryption requirements, integrity requirements, retention, privacy and other confidentiality requirements, and that these are applied in the architecture.
A30: V1.9 | B30: Communications Architecture | C30: 1.9.1 | D30: 2 | E30: 319 | G30: Verify the application encrypts communications between components, particularly when these components are in different containers, systems, sites, or cloud providers. ([C3](https://owasp.org/www-project-proactive-controls/#div-numbering))
C31: 1.9.2 | D31: 2 | E31: 295 | G31: Verify that application components verify the authenticity of each side in a communication link to prevent person-in-the-middle attacks. For example, application components should validate TLS certificates and chains.
A32: V1.10 | B32: Malicious Software Architecture | C32: 1.10.1 | D32: 2 | E32: 284 | G32: Verify that a source code control system is in use, with procedures to ensure that check-ins are accompanied by issues or change tickets. The source code control system should have access control and identifiable users to allow traceability of any changes.
A33: V1.11 | B33: Business Logic Architecture | C33: 1.11.1 | D33: 2 | E33: 1059 | G33: Verify the definition and documentation of all application components in terms of the business or security functions they provide.
C34: 1.11.2 | D34: 2 | E34: 362 | G34: Verify that all high-value business logic flows, including authentication, session management and access control, do not share unsynchronized state.
C35: 1.11.3 | D35: 3 | E35: 367 | G35: Verify that all high-value business logic flows, including authentication, session management and access control are thread safe and resistant to time-of-check and time-of-use race conditions.
A36: V1.12 | B36: Secure File Upload Architecture | C36: 1.12.1 | G36: [DELETED, DUPLICATE OF 12.4.1]
C37: 1.12.2 | D37: 2 | E37: 646 | G37: Verify that user-uploaded files - if required to be displayed or downloaded from the application - are served by either octet stream downloads, or from an unrelated domain, such as a cloud file storage bucket. Implement a suitable Content Security Policy (CSP) to reduce the risk from XSS vectors or other attacks from the uploaded file.
A38: V1.14 | B38: Configuration Architecture | C38: 1.14.1 | D38: 2 | E38: 923 | G38: Verify the segregation of components of differing trust levels through well-defined security controls, firewall rules, API gateways, reverse proxies, cloud-based security groups, or similar mechanisms.
C39: 1.14.2 | D39: 2 | E39: 494 | G39: Verify that binary signatures, trusted connections, and verified endpoints are used to deploy binaries to remote devices.
C40: 1.14.3 | D40: 2 | E40: 1104 | G40: Verify that the build pipeline warns of out-of-date or insecure components and takes appropriate actions.
...

Sheet V2 - Authentication
A1: # | B1: Control Objective | C1: # | D1: ASVS Level | E1: CWE | F1: NIST | G1: Verification Requirement | H1: Valid | I1: Source Code Reference | J1: Comment | K1: Tool Used | L1: Scope
A2: V2.1 | B2: Password Security | C2: 2.1.1 | D2: 1 | E2: 521 | F2: 5.1.1.2 | G2: Verify that user set passwords are at least 12 characters in length (after multiple spaces are combined). ([C6](https://owasp.org/www-project-proactive-controls/#div-numbering))
C3: 2.1.2 | D3: 1 | E3: 521 | F3: 5.1.1.2 | G3: Verify that passwords of at least 64 characters are permitted, and that passwords of more than 128 characters are denied. ([C6](https://owasp.org/www-project-proactive-controls/#div-numbering))
C4: 2.1.3 | D4: 1 | E4: 521 | F4: 5.1.1.2 | G4: Verify that password truncation is not performed. However, consecutive multiple spaces may be replaced by a single space. ([C6](https://owasp.org/www-project-proactive-controls/#div-numbering))
C5: 2.1.4 | D5: 1 | E5: 521 | F5: 5.1.1.2 | G5: Verify that any printable Unicode character, including language neutral characters such as spaces and Emojis are permitted in passwords.
C6: 2.1.5 | D6: 1 | E6: 620 | F6: 5.1.1.2 | G6: Verify users can change their password.
C7: 2.1.6 | D7: 1 | E7: 620 | F7: 5.1.1.2 | G7: Verify that password change functionality requires the user's current and new password.
C8: 2.1.7 | D8: 1 | E8: 521 | F8: 5.1.1.2 | G8: Verify that passwords submitted during account registration, login, and password change are checked against a set of breached passwords either locally (such as the top 1,000 or 10,000 most common passwords which match the system's password policy) or using an external API. If using an API a zero knowledge proof or other mechanism should be used to ensure that the plain text password is not sent or used in verifying the breach status of the password. If the password is breached, the application must require the user to set a new non-breached password. ([C6](https://owasp.org/www-project-proactive-controls/#div-numbering))
C9: 2.1.8 | D9: 1 | E9: 521 | F9: 5.1.1.2 | G9: Verify that a password strength meter is provided to help users set a stronger password.
C10: 2.1.9 | D10: 1 | E10: 521 | F10: 5.1.1.2 | G10: Verify that there are no password composition rules limiting the type of characters permitted. There should be no requirement for upper or lower case or numbers or special characters. ([C6](https://owasp.org/www-project-proactive-controls/#div-numbering))
C11: 2.1.10 | D11: 1 | E11: 263 | F11: 5.1.1.2 | G11: Verify that there are no periodic credential rotation or password history requirements.
C12: 2.1.11 | D12: 1 | E12: 521 | F12: 5.1.1.2 | G12: Verify that "paste" functionality, browser password helpers, and external password managers are permitted.
C13: 2.1.12 | D13: 1 | E13: 521 | F13: 5.1.1.2 | G13: Verify that the user can choose to either temporarily view the entire masked password, or temporarily view the last typed character of the password on platforms that do not have this as built-in functionality.
A14: V2.2 | B14: General Authenticator | C14: 2.2.1 | D14: 1 | E14: 307 | F14: 5.2.2 5.1.1.2 5.1.4.2 5.1.5.2 | G14: Verify that anti-automation controls are effective at mitigating breached credential testing, brute force, and account lockout attacks. Such controls include blocking the most common breached passwords, soft lockouts, rate limiting, CAPTCHA, ever increasing delays between attempts, IP address restrictions, or risk-based restrictions such as location, first login on a device, recent attempts to unlock the account, or similar. Verify that no more than 100 failed attempts per hour is possible on a single account.
C15: 2.2.2 | D15: 1 | E15: 304 | F15: 5.2.10 | G15: Verify that the use of weak authenticators (such as SMS and email) is limited to secondary verification and transaction approval and not as a replacement for more secure authentication methods. Verify that stronger methods are offered before weak methods, users are aware of the risks, or that proper measures are in place to limit the risks of account compromise.
C16: 2.2.3 | D16: 1 | E16: 620 | G16: Verify that secure notifications are sent to users after updates to authentication details, such as credential resets, email or address changes, logging in from unknown or risky locations. The use of push notifications - rather than SMS or email - is preferred, but in the absence of push notifications, SMS or email is acceptable as long as no sensitive information is disclosed in the notification.
C17: 2.2.4 | D17: 3 | E17: 308 | F17: 5.2.5 | G17: Verify impersonation resistance against phishing, such as the use of multi-factor authentication, cryptographic devices with intent (such as connected keys with a push to authenticate), or at higher AAL levels, client-side certificates.
C18: 2.2.5 | D18: 3 | E18: 319 | F18: 5.2.6 | G18: Verify that where a Credential Service Provider (CSP) and the application verifying authentication are separated, mutually authenticated TLS is in place between the two endpoints.
C19: 2.2.6 | D19: 3 | E19: 308 | F19: 5.2.8 | G19: Verify replay resistance through the mandated use of One-time Passwords (OTP) devices, cryptographic authenticators, or lookup codes.
C20: 2.2.7 | D20: 3 | E20: 308 | F20: 5.2.9 | G20: Verify intent to authenticate by requiring the entry of an OTP token or user-initiated action such as a button press on a FIDO hardware key.
A21: V2.3 | B21: Authenticator Lifecycle | C21: 2.3.1 | D21: 1 | E21: 330 | F21: 5.1.1.2 A. 3 | G21: Verify system generated initial passwords or activation codes SHOULD be securely randomly generated, SHOULD be at least 6 characters long, and MAY contain letters and numbers, and expire after a short period of time. These initial secrets must not be permitted to become the long term password.
C22: 2.3.2 | D22: 2 | E22: 308 | F22: 6.1.3 | G22: Verify that enrollment and use of subscriber-provided authentication devices are supported, such as a U2F or FIDO tokens.
C23: 2.3.3 | D23: 2 | E23: 287 | F23: 6.1.4 | G23: Verify that renewal instructions are sent with sufficient time to renew time bound authenticators.
A24: V2.4 | B24: Credentials Storage Credentials | C24: 2.4.1 | D24: 2 | E24: 916 | F24: 5.1.1.2 | G24: Verify that passwords are stored in a form that is resistant to offline attacks. Passwords SHALL be salted and hashed using an approved one-way key derivation or password hashing function. Key derivation and password hashing functions take a password, a salt, and a cost factor as inputs when generating a password hash. ([C6](https://owasp.org/www-project-proactive-controls/#div-numbering))
C25: 2.4.2 | D25: 2 | E25: 916 | F25: 5.1.1.2 | G25: Verify that the salt is at least 32 bits in length and be chosen arbitrarily to minimize salt value collisions among stored hashes. For each credential, a unique salt value and the resulting hash SHALL be stored. ([C6](https://owasp.org/www-project-proactive-controls/#div-numbering))
C26: 2.4.3 | D26: 2 | E26: 916 | F26: 5.1.1.2 | G26: Verify that if PBKDF2 is used, the iteration count SHOULD be as large as verification server performance will allow, typically at least 100,000 iterations. ([C6](https://owasp.org/www-project-proactive-controls/#div-numbering))
C27: 2.4.4 | D27: 2 | E27: 916 | F27: 5.1.1.2 | G27: Verify that if bcrypt is used, the work factor SHOULD be as large as verification server performance will allow, with a minimum of 10. ([C6](https://owasp.org/www-project-proactive-controls/#div-numbering))
C28: 2.4.5 | D28: 2 | E28: 916 | F28: 5.1.1.2 | G28: Verify that an additional iteration of a key derivation function is performed, using a salt value that is secret and known only to the verifier. Generate the salt value using an approved random bit generator [SP 800-90Ar1] and provide at least the minimum security strength specified in the latest revision of SP 800-131A. The secret salt value SHALL be stored separately from the hashed passwords (e.g., in a specialized device like a hardware security module).
A29: V2.5 | B29: Credential Recovery | C29: 2.5.1 | D29: 1 | E29: 640 | F29: 5.1.1.2 | G29: Verify that a system generated initial activation or recovery secret is not sent in clear text to the user. ([C6](https://owasp.org/www-project-proactive-controls/#div-numbering))
C30: 2.5.2 | D30: 1 | E30: 640 | F30: 5.1.1.2 | G30: Verify password hints or knowledge-based authentication (so-called "secret questions") are not present.
C31: 2.5.3 | D31: 1 | E31: 640 | F31: 5.1.1.2 | G31: Verify password credential recovery does not reveal the current password in any way. ([C6](https://owasp.org/www-project-proactive-controls/#div-numbering))
C32: 2.5.4 | D32: 1 | E32: 16 | F32: 5.1.1.2 A. 3 | G32: Verify shared or default accounts are not present (e.g. "root", "admin", or "sa").
C33: 2.5.5 | D33: 1 | E33: 304 | F33: 6.1.2.3 | G33: Verify that if an authentication factor is changed or replaced, that the user is notified of this event.
C34: 2.5.6 | D34: 1 | E34: 640 | F34: 5.1.1.2 | G34: Verify forgotten password, and other recovery paths use a secure recovery mechanism, such as time-based OTP (TOTP) or other soft token, mobile push, or another offline recovery mechanism. ([C6](https://owasp.org/www-project-proactive-controls/#div-numbering))
C35: 2.5.7 | D35: 2 | E35: 308 | F35: 6.1.2.3 | G35: Verify that if OTP or multi-factor authentication factors are lost, that evidence of identity proofing is performed at the same level as during enrollment.
A36: V2.6 | B36: Look-up Secret Verifier | C36: 2.6.1 | D36: 2 | E36: 308 | F36: 5.1.2.2 | G36: Verify that lookup secrets can be used only once.
C37: 2.6.2 | D37: 2 | E37: 330 | F37: 5.1.2.2 | G37: Verify that lookup secrets have sufficient randomness (112 bits of entropy), or if less than 112 bits of entropy, salted with a unique and random 32-bit salt and hashed with an approved one-way hash.
C38: 2.6.3 | D38: 2 | E38: 310 | F38: 5.1.2.2 | G38: Verify that lookup secrets are resistant to offline attacks, such as predictable values.
A39: V2.7 | B39: Out of Band Verifier | C39: 2.7.1 | D39: 1 | E39: 287 | F39: 5.1.3.2 | G39: Verify that clear text out of band (NIST "restricted") authenticators, such as SMS or PSTN, are not offered by default, and stronger alternatives such as push notifications are offered first.
C40: 2.7.2 | D40: 1 | E40: 287 | F40: 5.1.3.2 | G40: Verify that the out of band verifier expires out of band authentication requests, codes, or tokens after 10 minutes.
...

Sheet V3 - Session Management
A1: # | B1: Control Objective | C1: # | D1: ASVS Level | E1: CWE | F1: NIST | G1: Verification Requirement | H1: Valid | I1: Source Code Reference | J1: Comment | K1: Tool Used | L1: Scope
A2: V3.1 | B2: Fundamental Session Management | C2: 3.1.1 | D2: 1 | E2: 598 | G2: Verify the application never reveals session tokens in URL parameters.
A3: V3.2 | B3: Session Binding | C3: 3.2.1 | D3: 1 | E3: 384 | F3: 7.1 | G3: Verify the application generates a new session token on user authentication. ([C6](https://www.owasp.org/index.php/OWASP_Proactive_Controls#tab=Formal_Numbering))
C4: 3.2.2 | D4: 1 | E4: 331 | F4: 7.1 | G4: Verify that session tokens possess at least 64 bits of entropy. ([C6](https://www.owasp.org/index.php/OWASP_Proactive_Controls#tab=Formal_Numbering))
C5: 3.2.3 | D5: 1 | E5: 539 | F5: 7.1 | G5: Verify the application only stores session tokens in the browser using secure methods such as appropriately secured cookies (see section 3.4) or HTML 5 session storage.
C6: 3.2.4 | D6: 2 | E6: 331 | F6: 7.1 | G6: Verify that session token are generated using approved cryptographic algorithms. ([C6](https://www.owasp.org/index.php/OWASP_Proactive_Controls#tab=Formal_Numbering))
A7: V3.3 | B7: Session Termination | C7: 3.3.1 | D7: 1 | E7: 613 | F7: 7.1 | G7: Verify that logout and expiration invalidate the session token, such that the back button or a downstream relying party does not resume an authenticated session, including across relying parties. ([C6](https://owasp.org/www-project-proactive-controls/#div-numbering))
C8: 3.3.2 | D8: 1 | E8: 613 | F8: 7.2 | G8: If authenticators permit users to remain logged in, verify that re-authentication occurs periodically both when actively used or after an idle period. ([C6](https://owasp.org/www-project-proactive-controls/#div-numbering)) * L1: 30 days * L2: 12 hours or 30 minutes of inactivity, 2FA optional * L3: 12 hours or 15 minutes of inactivity, with 2FA
C9: 3.3.3 | D9: 2 | E9: 613 | G9: Verify that the application gives the option to terminate all other active sessions after a successful password change (including change via password reset/recovery), and that this is effective across the application, federated login (if present), and any relying parties.
C10: 3.3.4 | D10: 2 | E10: 613 | F10: 7.1 | G10: Verify that users are able to view and (having re-entered login credentials) log out of any or all currently active sessions and devices.
A11: V3.4 | B11: Cookie-based Session Management | C11: 3.4.1 | D11: 1 | E11: 614 | F11: 7.1.1 | G11: Verify that cookie-based session tokens have the 'Secure' attribute set. ([C6](https://owasp.org/www-project-proactive-controls/#div-numbering))
C12: 3.4.2 | D12: 1 | E12: 1004 | F12: 7.1.1 | G12: Verify that cookie-based session tokens have the 'HttpOnly' attribute set. ([C6](https://owasp.org/www-project-proactive-controls/#div-numbering))
C13: 3.4.3 | D13: 1 | E13: 16 | F13: 7.1.1 | G13: Verify that cookie-based session tokens utilize the 'SameSite' attribute to limit exposure to cross-site request forgery attacks. ([C6](https://owasp.org/www-project-proactive-controls/#div-numbering))
C14: 3.4.4 | D14: 1 | E14: 16 | F14: 7.1.1 | G14: Verify that cookie-based session tokens use "__Host-" prefix (see references) to provide session cookie confidentiality.
C15: 3.4.5 | D15: 1 | E15: 16 | F15: 7.1.1 | G15: Verify that if the application is published under a domain name with other applications that set or use session cookies that might override or disclose the session cookies, set the path attribute in cookie-based session tokens using the most precise path possible. ([C6](https://owasp.org/www-project-proactive-controls/#div-numbering))
A16: V3.5 | B16: Token-based Session Management | C16: 3.5.1 | D16: 2 | E16: 290 | F16: 7.1.2 | G16: Verify the application allows users to revoke OAuth tokens that form trust relationships with linked applications.
C17: 3.5.2 | D17: 2 | E17: 798 | G17: Verify the application uses session tokens rather than static API secrets and keys, except with legacy implementations.
C18: 3.5.3 | D18: 2 | E18: 345 | G18: Verify that stateless session tokens use digital signatures, encryption, and other countermeasures to protect against tampering, enveloping, replay, null cipher, and key substitution attacks.
A19: V3.6 | B19: Federated Re-authentication | C19: 3.6.1 | D19: 3 | E19: 613 | F19: 7.2.1 | G19: Verify that Relying Parties (RPs) specify the maximum authentication time to Credential Service Providers (CSPs) and that CSPs re-authenticate the user if they haven't used a session within that period.
C20: 3.6.2 | D20: 3 | E20: 613 | F20: 7.2.1 | G20: Verify that Credential Service Providers (CSPs) inform Relying Parties (RPs) of the last authentication event, to allow RPs to determine if they need to re-authenticate the user.
A21: V3.7 | B21: Defenses Against Session Management Exploits | C21: 3.7.1 | D21: 1 | E21: 306 | G21: Verify the application ensures a valid login session or requires re-authentication or secondary verification before allowing any sensitive transactions or account modifications.

Sheet V4 - Access Control
A1: # | B1: Control Objective | C1: # | D1: ASVS Level | E1: CWE | F1: NIST | G1: Verification Requirement | H1: Valid | I1: Source Code Reference | J1: Comment | K1: Tool Used | L1: Scope
A2: V4.1 | B2: General Access Control Design | C2: 4.1.1 | D2: 1 | E2: 602 | G2: Verify that the application enforces access control rules on a trusted service layer, especially if client-side access control is present and could be bypassed.
C3: 4.1.2 | D3: 1 | E3: 639 | G3: Verify that all user and data attributes and policy information used by access controls cannot be manipulated by end users unless specifically authorized.
C4: 4.1.3 | D4: 1 | E4: 285 | G4: Verify that the principle of least privilege exists - users should only be able to access functions, data files, URLs, controllers, services, and other resources, for which they possess specific authorization. This implies protection against spoofing and elevation of privilege. ([C7](https://owasp.org/www-project-proactive-controls/#div-numbering))
C5: 4.1.4 | G5: [DELETED, DUPLICATE OF 4.1.3]
C6: 4.1.5 | D6: 1 | E6: 285 | G6: Verify that access controls fail securely including when an exception occurs. ([C10](https://owasp.org/www-project-proactive-controls/#div-numbering))
A7: V4.2 | B7: Operation Level Access Control | C7: 4.2.1 | D7: 1 | E7: 639 | G7: Verify that sensitive data and APIs are protected against Insecure Direct Object Reference (IDOR) attacks targeting creation, reading, updating and deletion of records, such as creating or updating someone else's record, viewing everyone's records, or deleting all records.
C8: 4.2.2 | D8: 1 | E8: 352 | G8: Verify that the application or framework enforces a strong anti-CSRF mechanism to protect authenticated functionality, and effective anti-automation or anti-CSRF protects unauthenticated functionality.
A9: V.4.3 | B9: Other Access Control Considerations | C9: 4.3.1 | D9: 1 | E9: 419 | G9: Verify administrative interfaces use appropriate multi-factor authentication to prevent unauthorized use.
C10: 4.3.2 | D10: 1 | E10: 548 | G10: Verify that directory browsing is disabled unless deliberately desired. Additionally, applications should not allow discovery or disclosure of file or directory metadata, such as Thumbs.db, .DS_Store, .git or .svn folders.
C11: 4.3.3 | D11: 2 | E11: 732 | G11: Verify the application has additional authorization (such as step up or adaptive authentication) for lower value systems, and / or segregation of duties for high value applications to enforce anti-fraud controls as per the risk of application and past fraud.

Sheet V5 - Validation, Sanitization a
A1: # | B1: Control Objective | C1: # | D1: ASVS Level | E1: CWE | F1: NIST | G1: Verification Requirement | H1: Valid | I1: Source Code Reference | J1: Comment | K1: Tool Used | L1: Scope
A2: V5.1 | B2: Input Validation | C2: 5.1.1 | D2: 1 | E2: 235 | G2: Verify that the application has defenses against HTTP parameter pollution attacks, particularly if the application framework makes no distinction about the source of request parameters (GET, POST, cookies, headers, or environment variables).
C3: 5.1.2 | D3: 1 | E3: 915 | G3: Verify that frameworks protect against mass parameter assignment attacks, or that the application has countermeasures to protect against unsafe parameter assignment, such as marking fields private or similar. ([C5](https://owasp.org/www-project-proactive-controls/#div-numbering))
C4: 5.1.3 | D4: 1 | E4: 20 | G4: Verify that all input (HTML form fields, REST requests, URL parameters, HTTP headers, cookies, batch files, RSS feeds, etc) is validated using positive validation (allow lists). ([C5](https://owasp.org/www-project-proactive-controls/#div-numbering))
C5: 5.1.4 | D5: 1 | E5: 20 | G5: Verify that structured data is strongly typed and validated against a defined schema including allowed characters, length and pattern (e.g. credit card numbers or telephone, or validating that two related fields are reasonable, such as checking that suburb and zip/postcode match). ([C5](https://owasp.org/www-project-proactive-controls/#div-numbering))
C6: 5.1.5 | D6: 1 | E6: 601 | G6: Verify that URL redirects and forwards only allow destinations which appear on an allow list, or show a warning when redirecting to potentially untrusted content.
A7: V5.2 | B7: Sanitization and Sandboxing | C7: 5.2.1 | D7: 1 | E7: 116 | G7: Verify that all untrusted HTML input from WYSIWYG editors or similar is properly sanitized with an HTML sanitizer library or framework feature. ([C5](https://owasp.org/www-project-proactive-controls/#div-numbering))
C8: 5.2.2 | D8: 1 | E8: 138 | G8: Verify that unstructured data is sanitized to enforce safety measures such as allowed characters and length.
C9: 5.2.3 | D9: 1 | E9: 147 | G9: Verify that the application sanitizes user input before passing to mail systems to protect against SMTP or IMAP injection.
C10: 5.2.4 | D10: 1 | E10: 95 | G10: Verify that the application avoids the use of eval() or other dynamic code execution features. Where there is no alternative, any user input being included must be sanitized or sandboxed before being executed.
C11: 5.2.5 | D11: 1 | E11: 94 | G11: Verify that the application protects against template injection attacks by ensuring that any user input being included is sanitized or sandboxed.
C12: 5.2.6 | D12: 1 | E12: 918 | G12: Verify that the application protects against SSRF attacks, by validating or sanitizing untrusted data or HTTP file metadata, such as filenames and URL input fields, and uses allow lists of protocols, domains, paths and ports.
C13: 5.2.7 | D13: 1 | E13: 159 | G13: Verify that the application sanitizes, disables, or sandboxes user-supplied Scalable Vector Graphics (SVG) scriptable content, especially as they relate to XSS resulting from inline scripts, and foreignObject.
C14: 5.2.8 | D14: 1 | E14: 94 | G14: Verify that the application sanitizes, disables, or sandboxes user-supplied scriptable or expression template language content, such as Markdown, CSS or XSL stylesheets, BBCode, or similar.
A15: V5.3 | B15: Output Encoding and Injection Prevention | C15: 5.3.1 | D15: 1 | E15: 116 | G15: Verify that output encoding is relevant for the interpreter and context required. For example, use encoders specifically for HTML values, HTML attributes, JavaScript, URL parameters, HTTP headers, SMTP, and others as the context requires, especially from untrusted inputs (e.g. names with Unicode or apostrophes, such as ねこ or O'Hara). ([C4](https://owasp.org/www-project-proactive-controls/#div-numbering))
C16: 5.3.2 | D16: 1 | E16: 176 | G16: Verify that output encoding preserves the user's chosen character set and locale, such that any Unicode character point is valid and safely handled. ([C4](https://owasp.org/www-project-proactive-controls/#div-numbering))
C17: 5.3.3 | D17: 1 | E17: 79 | G17: Verify that context-aware, preferably automated - or at worst, manual - output escaping protects against reflected, stored, and DOM based XSS. ([C4](https://owasp.org/www-project-proactive-controls/#div-numbering))
C18: 5.3.4 | D18: 1 | E18: 89 | G18: Verify that data selection or database queries (e.g. SQL, HQL, ORM, NoSQL) use parameterized queries, ORMs, entity frameworks, or are otherwise protected from database injection attacks. ([C3](https://owasp.org/www-project-proactive-controls/#div-numbering))
C19: 5.3.5 | D19: 1 | E19: 89 | G19: Verify that where parameterized or safer mechanisms are not present, context-specific output encoding is used to protect against injection attacks, such as the use of SQL escaping to protect against SQL injection. ([C3, C4](https://owasp.org/www-project-proactive-controls/#div-numbering))
C20: 5.3.6 | D20: 1 | E20: 830 | G20: Verify that the application protects against JSON injection attacks, JSON eval attacks, and JavaScript expression evaluation. ([C4](https://owasp.org/www-project-proactive-controls/#div-numbering))
C21: 5.3.7 | D21: 1 | E21: 943 | G21: Verify that the application protects against LDAP injection vulnerabilities, or that specific security controls to prevent LDAP injection have been implemented. ([C4](https://owasp.org/www-project-proactive-controls/#div-numbering))
C22: 5.3.8 | D22: 1 | E22: 78 | G22: Verify that the application protects against OS command injection and that operating system calls use parameterized OS queries or use contextual command line output encoding. ([C4](https://owasp.org/www-project-proactive-controls/#div-numbering))
C23: 5.3.9 | D23: 1 | E23: 829 | G23: Verify that the application protects against Local File Inclusion (LFI) or Remote File Inclusion (RFI) attacks.
C24: 5.3.10 | D24: 1 | E24: 643 | G24: Verify that the application protects against XPath injection or XML injection attacks. ([C4](https://owasp.org/www-project-proactive-controls/#div-numbering))
A25: V5.4 | B25: Memory, String and Unmanaged Code | C25: 5.4.1 | D25: 2 | E25: 120 | G25: Verify that the application uses memory-safe string, safer memory copy and pointer arithmetic to detect or prevent stack, buffer, or heap overflows.
C26: 5.4.2 | D26: 2 | E26: 134 | G26: Verify that format strings do not take potentially hostile input, and are constant.
C27: 5.4.3 | D27: 2 | E27: 190 | G27: Verify that sign, range, and input validation techniques are used to prevent integer overflows.
A28: V.5.5 | B28: Deserialization Prevention | C28: 5.5.1 | D28: 1 | E28: 502 | G28: Verify that serialized objects use integrity checks or are encrypted to prevent hostile object creation or data tampering. ([C5](https://owasp.org/www-project-proactive-controls/#div-numbering))
C29: 5.5.2 | D29: 1 | E29: 611 | G29: Verify that the application correctly restricts XML parsers to only use the most restrictive configuration possible and to ensure that unsafe features such as resolving external entities are disabled to prevent XML eXternal Entity (XXE) attacks.
C30: 5.5.3 | D30: 1 | E30: 502 | G30: Verify that deserialization of untrusted data is avoided or is protected in both custom code and third-party libraries (such as JSON, XML and YAML parsers).
C31: 5.5.4 | D31: 1 | E31: 95 | G31: Verify that when parsing JSON in browsers or JavaScript-based backends, JSON.parse is used to parse the JSON document. Do not use eval() to parse JSON.

Sheet V6 - Stored Cryptography
A1: # | B1: Control Objective | C1: # | D1: ASVS Level | E1: CWE | F1: NIST | G1: Verification Requirement | H1: Valid | I1: Source Code Reference | J1: Comment | K1: Tool Used | L1: Scope
A2: V6.1 | B2: Data Classification | C2: 6.1.1 | D2: 2 | E2: 311 | G2: Verify that regulated private data is stored encrypted while at rest, such as Personally Identifiable Information (PII), sensitive personal information, or data assessed likely to be subject to EU's GDPR.
C3: 6.1.2 | D3: 2 | E3: 311 | G3: Verify that regulated health data is stored encrypted while at rest, such as medical records, medical device details, or de-anonymized research records.
C4: 6.1.3 | D4: 2 | E4: 311 | G4: Verify that regulated financial data is stored encrypted while at rest, such as financial accounts, defaults or credit history, tax records, pay history, beneficiaries, or de-anonymized market or research records.
A5: V6.2 | B5: Algorithms | C5: 6.2.1 | D5: 1 | E5: 310 | G5: Verify that all cryptographic modules fail securely, and errors are handled in a way that does not enable Padding Oracle attacks.
C6: 6.2.2 | D6: 2 | E6: 327 | G6: Verify that industry proven or government approved cryptographic algorithms, modes, and libraries are used, instead of custom coded cryptography. ([C8](https://owasp.org/www-project-proactive-controls/#div-numbering))
C7: 6.2.3 | D7: 2 | E7: 326 | G7: Verify that encryption initialization vector, cipher configuration, and block modes are configured securely using the latest advice.
C8: 6.2.4 | D8: 2 | E8: 326 | G8: Verify that random number, encryption or hashing algorithms, key lengths, rounds, ciphers or modes, can be reconfigured, upgraded, or swapped at any time, to protect against cryptographic breaks. ([C8](https://owasp.org/www-project-proactive-controls/#div-numbering))
C9: 6.2.5 | D9: 2 | E9: 326 | G9: Verify that known insecure block modes (i.e. ECB, etc.), padding modes (i.e. PKCS#1 v1.5, etc.), ciphers with small block sizes (i.e. Triple-DES, Blowfish, etc.), and weak hashing algorithms (i.e. MD5, SHA1, etc.) are not used unless required for backwards compatibility.
C10: 6.2.6 | D10: 2 | E10: 326 | G10: Verify that nonces, initialization vectors, and other single use numbers must not be used more than once with a given encryption key. The method of generation must be appropriate for the algorithm being used.
C11: 6.2.7 | D11: 3 | E11: 326 | G11: Verify that encrypted data is authenticated via signatures, authenticated cipher modes, or HMAC to ensure that ciphertext is not altered by an unauthorized party.
C12: 6.2.8 | D12: 3 | E12: 385 | G12: Verify that all cryptographic operations are constant-time, with no 'short-circuit' operations in comparisons, calculations, or returns, to avoid leaking information.
A13: V6.3 | B13: Random values | C13: 6.3.1 | D13: 2 | E13: 338 | G13: Verify that all random numbers, random file names, random GUIDs, and random strings are generated using the cryptographic module's approved cryptographically secure random number generator when these random values are intended to be not guessable by an attacker.
C14: 6.3.2 | D14: 2 | E14: 338 | G14: Verify that random GUIDs are created using the GUID v4 algorithm, and a Cryptographically-secure Pseudo-random Number Generator (CSPRNG). GUIDs created using other pseudo-random number generators may be predictable.
C15: 6.3.3 | D15: 3 | E15: 338 | G15: Verify that random numbers are created with proper entropy even when the application is under heavy load, or that the application degrades gracefully in such circumstances.
A16: V6.4 | B16: Secret Management | C16: 6.4.1 | D16: 2 | E16: 798 | G16: Verify that a secrets management solution such as a key vault is used to securely create, store, control access to and destroy secrets. ([C8](https://owasp.org/www-project-proactive-controls/#div-numbering))
C17: 6.4.2 | D17: 2 | E17: 320 | G17: Verify that key material is not exposed to the application but instead uses an isolated security module like a vault for cryptographic operations. ([C8](https://owasp.org/www-project-proactive-controls/#div-numbering))

Sheet V7 - Error Handling and Logging
A1: # | B1: Control Objective | C1: # | D1: ASVS Level | E1: CWE | F1: NIST | G1: Verification Requirement | H1: Valid | I1: Source Code Reference | J1: Comment | K1: Tool Used | L1: Scope
A2: V7.1 | B2: Log Content | C2: 7.1.1 | D2: 1 | E2: 532 | G2: Verify that the application does not log credentials or payment details. Session tokens should only be stored in logs in an irreversible, hashed form. ([C9, C10](https://owasp.org/www-project-proactive-controls/#div-numbering))
C3: 7.1.2 | D3: 1 | E3: 532 | G3: Verify that the application does not log other sensitive data as defined under local privacy laws or relevant security policy. ([C9](https://owasp.org/www-project-proactive-controls/#div-numbering))
C4: 7.1.3 | D4: 2 | E4: 778 | G4: Verify that the application logs security relevant events including successful and failed authentication events, access control failures, deserialization failures and input validation failures. ([C5, C7](https://owasp.org/www-project-proactive-controls/#div-numbering))
C5: 7.1.4 | D5: 2 | E5: 778 | G5: Verify that each log event includes necessary information that would allow for a detailed investigation of the timeline when an event happens. ([C9](https://owasp.org/www-project-proactive-controls/#div-numbering))
A6: V7.2 | B6: Log Processing | C6: 7.2.1 | D6: 2 | E6: 778 | G6: Verify that all authentication decisions are logged, without storing sensitive session identifiers or passwords. This should include requests with relevant metadata needed for security investigations.
C7: 7.2.2 | D7: 2 | E7: 285 | G7: Verify that all access control decisions can be logged and all failed decisions are logged. This should include requests with relevant metadata needed for security investigations.
A8: V7.3 | B8: Log Protection | C8: 7.3.1 | D8: 2 | E8: 117 | G8: Verify that the application appropriately encodes user-supplied data to prevent log injection. ([C9](https://owasp.org/www-project-proactive-controls/#div-numbering))
C9: 7.3.2 | G9: [DELETED, DUPLICATE OF 7.3.1]
C10: 7.3.3 | D10: 2 | E10: 200 | G10: Verify that security logs are protected from unauthorized access and modification. ([C9](https://owasp.org/www-project-proactive-controls/#div-numbering))
C11: 7.3.4 | D11: 2 | G11: Verify that time sources are synchronized to the correct time and time zone. Strongly consider logging only in UTC if systems are global to assist with post-incident forensic analysis. ([C9](https://owasp.org/www-project-proactive-controls/#div-numbering))
A12: V7.4 | B12: Error Handling | C12: 7.4.1 | D12: 1 | E12: 210 | G12: Verify that a generic message is shown when an unexpected or security sensitive error occurs, potentially with a unique ID which support personnel can use to investigate. ([C10](https://owasp.org/www-project-proactive-controls/#div-numbering))
C13: 7.4.2 | D13: 2 | E13: 544 | G13: Verify that exception handling (or a functional equivalent) is used across the codebase to account for expected and unexpected error conditions. ([C10](https://owasp.org/www-project-proactive-controls/#div-numbering))
C14: 7.4.3 | D14: 2 | E14: 431 | G14: Verify that a "last resort" error handler is defined which will catch all unhandled exceptions. ([C10](https://owasp.org/www-project-proactive-controls/#div-numbering))

Sheet V8 - Data Protection
A1: # | B1: Control Objective | C1: # | D1: ASVS Level | E1: CWE | F1: NIST | G1: Verification Requirement | H1: Valid | I1: Source Code Reference | J1: Comment | K1: Tool Used | L1: Scope
A2: V8.1 | B2: General Data Protection | C2: 8.1.1 | D2: 2 | E2: 524 | G2: Verify the application protects sensitive data from being cached in server components such as load balancers and application caches.
C3: 8.1.2 | D3: 2 | E3: 524 | G3: Verify that all cached or temporary copies of sensitive data stored on the server are protected from unauthorized access or purged/invalidated after the authorized user accesses the sensitive data.
C4: 8.1.3 | D4: 2 | E4: 233 | G4: Verify the application minimizes the number of parameters in a request, such as hidden fields, Ajax variables, cookies and header values.
C5: 8.1.4 | D5: 2 | E5: 770 | G5: Verify the application can detect and alert on abnormal numbers of requests, such as by IP, user, total per hour or day, or whatever makes sense for the application.
C6: 8.1.5 | D6: 3 | E6: 19 | G6: Verify that regular backups of important data are performed and that test restoration of data is performed.
C7: 8.1.6 | D7: 3 | E7: 19 | G7: Verify that backups are stored securely to prevent data from being stolen or corrupted.
A8: V8.2 | B8: Client-side Data Protection | C8: 8.2.1 | D8: 1 | E8: 525 | G8: Verify the application sets sufficient anti-caching headers so that sensitive data is not cached in modern browsers.
C9: 8.2.2 | D9: 1 | E9: 922 | G9: Verify that data stored in browser storage (such as localStorage, sessionStorage, IndexedDB, or cookies) does not contain sensitive data.
C10: 8.2.3 | D10: 1 | E10: 922 | G10: Verify that authenticated data is cleared from client storage, such as the browser DOM, after the client or session is terminated.
A11: V8.3 | B11: Sensitive Private Data | C11: 8.3.1 | D11: 1 | E11: 319 | G11: Verify that sensitive data is sent to the server in the HTTP message body or headers, and that query string parameters from any HTTP verb do not contain sensitive data.
C12: 8.3.2 | D12: 1 | E12: 212 | G12: Verify that users have a method to remove or export their data on demand.
C13: 8.3.3 | D13: 1 | E13: 285 | G13: Verify that users are provided clear language regarding collection and use of supplied personal information and that users have provided opt-in consent for the use of that data before it is used in any way.
C14: 8.3.4 | D14: 1 | E14: 200 | G14: Verify that all sensitive data created and processed by the application has been identified, and ensure that a policy is in place on how to deal with sensitive data. ([C8](https://owasp.org/www-project-proactive-controls/#div-numbering))
C15: 8.3.5 | D15: 2 | E15: 532 | G15: Verify accessing sensitive data is audited (without logging the sensitive data itself), if the data is collected under relevant data protection directives or where logging of access is required.
C16: 8.3.6 | D16: 2 | E16: 226 | G16: Verify that sensitive information contained in memory is overwritten as soon as it is no longer required to mitigate memory dumping attacks, using zeroes or random data.
C17: 8.3.7 | D17: 2 | E17: 327 | G17: Verify that sensitive or private information that is required to be encrypted, is encrypted using approved algorithms that provide both confidentiality and integrity. ([C8](https://owasp.org/www-project-proactive-controls/#div-numbering))
C18: 8.3.8 | D18: 2 | E18: 285 | G18: Verify that sensitive personal information is subject to data retention classification, such that old or out of date data is deleted automatically, on a schedule, or as the situation requires.

Sheet V9 - Communication
A1: # | B1: Control Objective | C1: # | D1: ASVS Level | E1: CWE | F1: NIST | G1: Verification Requirement | H1: Valid | I1: Source Code Reference | J1: Comment | K1: Tool Used | L1: Scope
A2: V9.1 | B2: Client Communications Security | C2: 9.1.1 | D2: 1 | E2: 319 | G2: Verify that TLS is used for all client connectivity, and does not fall back to insecure or unencrypted communications. ([C8](https://owasp.org/www-project-proactive-controls/#div-numbering))
C3: 9.1.2 | D3: 1 | E3: 326 | G3: Verify using up to date TLS testing tools that only strong cipher suites are enabled, with the strongest cipher suites set as preferred.
C4: 9.1.3 | D4: 1 | E4: 326 | G4: Verify that only the latest recommended versions of the TLS protocol are enabled, such as TLS 1.2 and TLS 1.3. The latest version of the TLS protocol should be the preferred option.
A5: V9.2 | B5: Server Communications Security | C5: 9.2.1 | D5: 2 | E5: 295 | G5: Verify that connections to and from the server use trusted TLS certificates. Where internally generated or self-signed certificates are used, the server must be configured to only trust specific internal CAs and specific self-signed certificates. All others should be rejected.
C6: 9.2.2 | D6: 2 | E6: 319 | G6: Verify that encrypted communications such as TLS is used for all inbound and outbound connections, including for management ports, monitoring, authentication, API, or web service calls, database, cloud, serverless, mainframe, external, and partner connections. The server must not fall back to insecure or unencrypted protocols.
C7: 9.2.3 | D7: 2 | E7: 287 | G7: Verify that all encrypted connections to external systems that involve sensitive information or functions are authenticated.
C8: 9.2.4 | D8: 2 | E8: 299 | G8: Verify that proper certification revocation, such as Online Certificate Status Protocol (OCSP) Stapling, is enabled and configured.
C9: 9.2.5 | D9: 3 | E9: 544 | G9: Verify that backend TLS connection failures are logged.

Sheet V10 - Malicious Code
A1: # | B1: Control Objective | C1: # | D1: ASVS Level | E1: CWE | F1: NIST | G1: Verification Requirement | H1: Valid | I1: Source Code Reference | J1: Comment | K1: Tool Used | L1: Scope
A2: V10.1 | B2: Code Integrity | C2: 10.1.1 | D2: 3 | E2: 749 | G2: Verify that a code analysis tool is in use that can detect potentially malicious code, such as time functions, unsafe file operations and network connections.
A3: V10.2 | B3: Malicious Code Search | C3: 10.2.1 | D3: 2 | E3: 359 | G3: Verify that the application source code and third party libraries do not contain unauthorized phone home or data collection capabilities. Where such functionality exists, obtain the user's permission for it to operate before collecting any data.
